data/output_file.csv
#name: scenario 1
#descr: balanced book

A, IBM, 1, 1
B, IBM, B, 10, 100
A, IBM, 1, 2
B, IBM, S, 12, 100
A, IBM, 2, 101
A, IBM, 2, 102 
B, IBM, S, 11, 100

A, IBM 1, 3
T, IBM, 1, 3, 2, 102, 11, 100
B, IBM, S, 12, 100
A, IBM, 2, 103
T, IBM, 1, 1, 2, 103, 10, 100
B, IBM, B, 9, 100

A, IBM, 1, 4
B, IBM, B, 10, 100
A, IBM, 2, 104
B, IBM, S, 11, 100

#name: scenario 3
#descr: shallow ask

A, VAL, 1, 1
B, VAL, B, 10, 100
A, VAL, 2, 101
A, VAL, 2, 102
B, VAL, S, 11, 100
A, VAL, 1, 2
T, VAL, 1, 2, 2, 102, 11, 100
B, VAL, S, -, -
A, VAL, 2, 103
B, VAL, S, 11, 100

#name: scenario 5
#descr: balanced book, limit above best ask

A, IBM, 1, 1
B, IBM, B, 10, 100
A, IBM, 1, 2
B, IBM, S, 12, 100
A, IBM, 2, 101
A, IBM, 2, 102 
B, IBM, S, 11, 100
A, IBM, 1, 103
T, IBM, 1, 103, 2, 102, 11, 100
B, IBM, S, 12, 100

#name: scenario 7
#descr: balanced book, market buy

A, IBM, 1, 1
B, IBM, B, 10, 100
A, IBM, 1, 2
B, IBM, S, 12, 100
A, IBM, 2, 101
A, IBM, 2, 102 
B, IBM, S, 11, 100
A, IBM, 1, 3
T, IBM, 1, 3, 2, 102, 11, 100
B, IBM, S, 12, 100

#name: scenario 9
#descr: balanced book, market sell partial

A, IBM, 1, 1
B, IBM, B, 10, 100
A, IBM, 1, 2
B, IBM, S, 12, 100
A, IBM, 2, 101
A, IBM, 2, 102 
B, IBM, S, 11, 100
A, IBM, 2, 103
T, IBM, 1, 1, 2, 103, 10, 20
B, IBM, B, 10, 80

#name: scenario 11
#descr: balanced book, limit sell partial

A, IBM, 1, 1
B, IBM, B, 10, 100
A, IBM, 1, 2
B, IBM, S, 12, 100
A, IBM, 2, 101
A, IBM, 2, 102 
B, IBM, S, 11, 100
A, IBM, 2, 103
T, IBM, 1, 1, 2, 103, 10, 20
B, IBM, B, 10, 80

#name: scenario 13
#descr: balanced book multiple orders at best bid offer

A, IBM, 1, 1
B, IBM, B, 10, 100
A, IBM, 1, 2
B, IBM, S, 12, 100
A, IBM, 2, 101
A, IBM, 2, 102 
B, IBM, S, 11, 100
A, IBM, 2, 103
B, IBM, B, 10, 150
A, IBM, 1, 3
B, IBM, S, 11, 150
A, IBM, 1, 4
T, IBM, 1, 4, 2, 102, 11, 100
B, IBM, S, 11, 50
A, IBM, 2, 104
T, IBM, 1, 1, 2, 104, 10, 100
B, IBM, B, 10, 50

#name: scenario 15
#descr: balanced book, cancel behind best bid and offer

A, IBM, 1, 1
B, IBM, B, 10, 100
A, IBM, 1, 2
B, IBM, S, 12, 100
A, IBM, 2, 101
A, IBM, 2, 102 
B, IBM, S, 11, 100
C, IBM, 1, 2
C, IBM, 2, 101
